Workbook

Sheet Hoja5
A1: MES | B1: FECHA | C1: DESCRIPCIÓN | D1: MONTO ($) | E1: SALDO ($) | F1: ABONO/CARGO | G1: CATEGORIA
A2: MAYO 2025 | B2: 45779.698 | C2: Mc Donalds Santiago Chl | D2: -2590 | E2: 4855508 | F2: Cargo | G2: Alimentación
A3: MAYO 2025 | B3: 45781.751 | C3: Cps Copec Pve Santiago Chl | D3: -550 | E3: 4752452 | F3: Cargo | G3: Alimentación
A4: MAYO 2025 | B4: 45785.816 | C4: Cps Copec Pve Santiago Chl | D4: -1950 | E4: 4928104 | F4: Cargo | G4: Alimentación
A5: MAYO 2025 | B5: 45790.475 | C5: Cps Copec Pve Santiago Chl | D5: -1950 | E5: 5095220 | F5: Cargo | G5: Alimentación
A6: MAYO 2025 | B6: 45790.884 | C6: Copec App Santiago Chl | D6: -1090 | E6: 5018270 | F6: Cargo | G6: Alimentación
A7: MAYO 2025 | B7: 45791.497 | C7: Mc Donalds Santiago Chl | D7: -6090 | E7: 4925996 | F7: Cargo | G7: Alimentación
A8: MAYO 2025 | B8: 45808.851 | C8: Mc Donalds Santiago Chl | D8: -5580 | E8: 3539692 | F8: Cargo | G8: Alimentación
A9: MAYO 2025 | B9: 45795.63 | C9: Cps Copec Pve Santiago Chl | D9: -2750 | E9: 4354753 | F9: Cargo | G9: Alimentación
A10: MAYO 2025 | B10: 45782.355 | C10: Transferencia En Linea A Otro Banco Fernando Arriagada | D10: -703000 | E10: 1517994 | F10: Cargo | G10: Arriendo
A11: MAYO 2025 | B11: 45780.604 | C11: Shell Ep580 Irarra4123 Santiago Chl | D11: -10000 | E11: 4794452 | F11: Cargo | G11: Bencina
A12: MAYO 2025 | B12: 45781.43 | C12: Shell Ep324 Alessdri26 Santiago Chl | D12: -10000 | E12: 4773452 | F12: Cargo | G12: Bencina
A13: MAYO 2025 | B13: 45782.872 | C13: Shel Walker Martinez F Santiago Chl | D13: -10000 | E13: 4521917 | F13: Cargo | G13: Bencina
... A86: MAYO 2025 | B86: 45802.82 | C86: Unimarc Rojas Magallan Santiago Chl | D86: -38350 | E86: 3709800 | F86: Cargo | G86: Supermercado
A87: MAYO 2025 | B87: 45806.922 | C87: Mercadopago *Reiteval Las Condes Chl | D87: -50 | E87: 1666630 | F87: Cargo
A88: MAYO 2025 | B88: 45781.794 | C88: Mall Paseo Quilin Santiago Chl | D88: -800 | E88: 1583359 | F88: Cargo
A89: MAYO 2025 | B89: 45793.56 | C89: Haulmer*botilleria Ech Santiago Chl | D89: -950 | E89: 1304113 | F89: Cargo
A90: MAYO 2025 | B90: 45807.491 | C90: Plaza Vespucio Santiago Chl | D90: -1000 | E90: 1358365 | F90: Cargo
A91: MAYO 2025 | B91: 45798.793 | C91: Tuu*holyfritas Santiago Chl | D91: -1200 | E91: 337438 | F91: Cargo
A92: MAYO 2025 | B92: 45790.448 | C92: Mercadopago *Ccuvendi Las Condes Chl | D92: -1600 | E92: 313688 | F92: Cargo
A93: MAYO 2025 | B93: 45798.483 | C93: Mercadopago *Ccuvendi Las Condes Chl | D93: -1600 | E93: 312088 | F93: Cargo
A94: MAYO 2025 | B94: 45806.508 | C94: Mercadopago *Ccuvendi Las Condes Chl | D94: -1600 | E94: 324322 | F94: Cargo
A95: MAYO 2025 | B95: 45807.552 | C95: Mercadopago *Ccuvendi Las Condes Chl | D95: -1600 | E95: 322722 | F95: Cargo
A96: MAYO 2025 | B96: 45808.849 | C96: Merpago*dunkin Fagase Lampa Chl | D96: -1730 | E96: 307141 | F96: Cargo
A97: MAYO 2025 | B97: 45790.689 | C97: Maxik Las Condes Chl | D97: -1890 | E97: 150755 | F97: Cargo
A98: MAYO 2025 | B98: 45783.387 | C98: Marina Hoteles Ltda- S Santiago Chl | D98: -1900 | E98: 216568 | F98: Cargo
... A154: MAYO 2025 | B154: 45787.709 | C154: Tb Factory Spa Penalolen Chl | D154: -39990 | E154: 4169020 | F154: Cargo

Sheet Historico
D2: Rendición | E2: 85650
D3: Saldo Tarjeta Debito BR | E3: 107041
D4: Saldo Tarjeta Credito BR | E4: 3701
D5: Saldo Tarjeta Credito BF | E5: 9357
D6: Otros | E6: 500000
D7: Abono Quincena | E7: 450000
D8: Efectivo | E8: 10000
D9: TOTAL | E9: =SUM(E2:E8) -> 1165749 | F9: =+E9+E2 -> 1251399
B10: MES | C10: FECHA | D10: DESCRIPCIÓN | E10: MONTO ($) | F10: ABONO/CARGO | G10: DEB/CRED. | H10: FIJO/VAR. | I10: CATEGORIA | K10: 106105
B11: 2026.10 OCTUBRE | C11: 46316 | D11: Meli Dólar | E11: -38 | F11: Abono | I11: Beneficio Meli
B12: 2026.10 OCTUBRE | C12: 46316 | D12: Libreria Artelapiz | E12: 7630 | F12: Cargo | G12: Debito | H12: Gastos Variables | I12: Colegio
B13: 2026.10 OCTUBRE | C13: 46316 | D13: Meli Dólar | E13: -4 | F13: Abono | I13: Beneficio Meli
B14: 2026.10 OCTUBRE | C14: 46316 | D14: Outletfit | E14: 700 | F14: Cargo | G14: Debito | H14: Gastos Variables | I14: Gastos varios
B15: 2026.10 OCTUBRE | C15: 46316 | D15: Meli Dólar | E15: -22 | F15: Abono | I15: Beneficio Meli
B16: 2026.10 OCTUBRE | C16: 46316 | D16: Sodexochile | E16: 4459 | F16: Cargo | G16: Debito | H16: Gastos Fijos | I16: Alimentación
B17: 2026.10 OCTUBRE | C17: 46316 | D17: Meli+ | E17: 2990 | F17: Cargo | G17: Debito | H17: Gastos Fijos | I17: Suscripción
B18: 2026.10 OCTUBRE | C18: 46316 | D18: Meli Dólar | E18: -9 | F18: Abono | I18: Beneficio Meli
B19: 2026.10 OCTUBRE | C19: 46316 | D19: Sodexochile | E19: 1700 | F19: Cargo | G19: Debito | H19: Gastos Variables | I19: Gastos varios
B20: 2026.10 OCTUBRE | C20: 46315 | D20: Uber Pagos Chile | E20: -93410 | F20: Abono | I20: Uber
B21: 2026.10 OCTUBRE | C21: 46315 | D21: Mercado Pago | E21: -3 | F21: Abono | I21: Beneficio Meli
B22: 2026.10 OCTUBRE | C22: 46315 | D22: Meli Dólar | E22: -20 | F22: Abono | I22: Beneficio Meli
B23: 2026.10 OCTUBRE | C23: 46315 | D23: Saudaveis | E23: 3960 | F23: Cargo | G23: Debito | H23: Gastos Variables | I23: Gastos varios
B24: 2026.10 OCTUBRE | C24: 46315 | D24: Meli Dólar | E24: -26 | F24: Abono | I24: Beneficio Meli
B25: 2026.10 OCTUBRE | C25: 46315 | D25: Fudo La Fika Panade | E25: 5190 | F25: Cargo | G25: Debito | H25: Gastos Variables | I25: Gastos varios
B26: 2026.10 OCTUBRE | C26: 46315 | D26: Meli Dólar | E26: -177 | F26: Abono | I26: Beneficio Meli
B27: 2026.10 OCTUBRE | C27: 46315 | D27: Unimarc Vicente Valdes | E27: 35392 | F27: Cargo | G27: Debito | H27: Gastos Variables | I27: Supermercado
B28: 2026.10 OCTUBRE | C28: 46315 | D28: Meli Dólar | E28: -159 | F28: Abono | I28: Beneficio Meli
B29: 2026.10 OCTUBRE | C29: 46315 | D29: Walker Martinez 315 | E29: 31890 | F29: Cargo | G29: Debito | H29: Gastos Variables | I29: Supermercado
B30: 2026.10 OCTUBRE | C30: 46315 | D30: Meli Dólar | E30: -50 | F30: Abono | I30: Beneficio Meli
B31: 2026.10 OCTUBRE | C31: 46315 | D31: Shell.f522 Av.p.ed Mon | E31: 10000 | F31: Cargo | G31: Debito | H31: Gastos Variables | I31: Bencina y Otros Auto
B32: 2026.10 OCTUBRE | C32: 46315 | D32: Meli Dólar | E32: -9 | F32: Abono | I32: Beneficio Meli
B33: 2026.10 OCTUBRE | C33: 46315 | D33: Sodexochile | E33: 1700 | F33: Cargo | G33: Debito | H33: Gastos Variables | I33: Gastos varios
B34: 2026.10 OCTUBRE | C34: 46314 | D34: Google One | E34: 1790 | F34: Cargo | G34: Debito | H34: Gastos Fijos | I34: Suscripción
B35: 2026.10 OCTUBRE | C35: 46314 | D35: Mercado Pago | E35: -4 | F35: Abono | I35: Beneficio Meli
B36: 2026.10 OCTUBRE | C36: 46314 | D36: Meli Dólar | E36: -22 | F36: Abono | I36: Beneficio Meli
B37: 2026.10 OCTUBRE | C37: 46314 | D37: Sodexochile | E37: 4459 | F37: Cargo | G37: Debito | H37: Gastos Fijos | I37: Alimentación
B38: 2026.10 OCTUBRE | C38: 46314 | D38: Alejandra Bozo | E38: 14000 | F38: Cargo | G38: Debito | H38: Gastos Variables | I38: Transf. Katy
B39: 2026.10 OCTUBRE | C39: 46314 | D39: Ingreso de dinero | E39: -106105 | F39: Abono | I39: Ahorro
B40: 2026.10 OCTUBRE | C40: 46314 | D40: Meli Dólar | E40: -8 | F40: Abono | I40: Beneficio Meli
B41: 2026.10 OCTUBRE | C41: 46314 | D41: Sodexochile | E41: 1500 | F41: Cargo | G41: Debito | H41: Gastos Variables | I41: Gastos varios
...

Sheet Hoja4
A1: Real | D1: Real Proyectado | I1: 9336 | J1: Uber | K1: =+(O1-1)*N4 -> 199500 | L1: Uber Proyección | M1: 46325 | N1: =+TODAY() -> 46316 | O1: =+M1-N1-1 -> 8
A2: Gastos fijos | B2: =+SUMIF(A46:A90,A2,B46:B90) -> 1277460 | C2: =+B2/B6 -> 0.32673299 | D2: Gastos Fijos | E2: =+SUMIF(G9:G37,D2,E9:E37) -> 1335938 | G2: =+E2/$E$6 -> 0.31228199 | I2: 585 | J2: Criptomoneda | K2: =+B39+I4+I3+I2+I1+K1 -> 4287807 | L2: =+'Dashboard Familiar'!F5 -> Ingreso esperado ($)
A3: Gastos variables | B3: =+SUMIF(A46:A91,A3,B46:B91) -> 2235338 | C3: =+B3/B6 -> 0.57172724 | D3: Gastos Variables | E3: =+SUMIF(G9:G37,D3,E9:E37) -> 2116127 | G3: =+E3/$E$6 -> 0.49465496 | I3: =3000+76492 -> 79492 | J3: Efectivo | N3: =+N4*7 -> 199500 | O3: Ingreso Semanal
A4: Ahorro | B4: =+SUMIF(A47:A92,A4,B47:B92) -> 397000 | C4: =+B4/B6 -> 0.10153977 | D4: Gastos Fijos/Var. | E4: =+SUMIF(G9:G37,D4,E9:E37) -> 428921 | G4: =+E4/$E$6 -> 0.10026237 | I4: 89096 | J4: Saldo Cuentas Cte. | L4: =+E39-B39 -> 368188 | N4: 28500 | O4: Ingreso Diario
D5: Ahorro | E5: =+SUMIF(G10:G38,D5,E10:E38) -> 397000 | G5: =+E5/$E$6 -> 0.092800678 | I5: =+B39+I2+I4+I1+I3-E39 -> -189679 | K5: =+L4/O1 -> 46023.5 | L5: =+I5+K1 -> 9821
A6: Total general | B6: =SUM(B2:B4) -> 3909798 | C6: =SUM(C2:C4) -> 1 | E6: =SUM(E2:E5) -> 4277986 | G6: =SUM(G2:G4) -> 0.90719932
A8: Descripción | B8: Gasto Real | C8: Proyectado | D8: Dif | E8: Gasto Real Proy. | F8: % | G8: Gastos Fijos/Var.
A9: Arriendo | B9: =+SUMIF($A$45:$A$90,A9,$B$45:$B$90) -> 758000 | C9: 758000 | D9: =+C9-B9 -> 0 | E9: =+MAX(B9:D9) -> 758000 | F9: =+E9/$E$39 -> 0.17718618 | G9: Gastos Fijos
A10: Supermercado | B10: =+SUMIF($A$45:$A$90,A10,$B$45:$B$90) -> 466965 | C10: 600000 | D10: =+C10-B10 -> 133035 | E10: =+MAX(B10:D10) -> 600000 | F10: =+E10/$E$39 -> 0.14025291 | G10: Gastos Variables
A11: Bencina y Otros Auto | B11: =+SUMIF($A$45:$A$90,A11,$B$45:$B$90) -> 507685 | C11: 580000 | D11: =+C11-B11 -> 72315 | E11: =+MAX(B11:D11) -> 580000 | F11: =+E11/$E$39 -> 0.13557782 | G11: Gastos Variables
A12: Fintual | B12: =+SUMIF($A$45:$A$90,A12,$B$45:$B$90) -> 397000 | C12: =+B12 -> 397000 | D12: =+C12-B12 -> 0 | E12: =+MAX(B12:D12) -> 397000 | F12: =+E12/$E$39 -> 0.092800678 | G12: Ahorro
A13: Transf. Katy | B13: =+SUMIF($A$45:$A$90,A13,$B$45:$B$90) -> 332091 | C13: =+B13 -> 332091 | D13: =+C13-B13 -> 0 | E13: =+MAX(B13:D13) -> 332091 | F13: =+E13/$E$39 -> 0.077627884 | G13: Gastos Fijos/Var.
A14: Gastos Comun | B14: =+SUMIF($A$45:$A$90,A14,$B$45:$B$90) -> 206427 | C14: 206427 | D14: =+C14-B14 -> 0 | E14: =+MAX(B14:D14) -> 206427 | F14: =+E14/$E$39 -> 0.048253314 | G14: Gastos Fijos
A15: Ropa | B15: =+SUMIF($A$45:$A$90,A15,$B$45:$B$90) -> 205195 | C15: 205195 | D15: =+C15-B15 -> 0 | E15: =+MAX(B15:D15) -> 205195 | F15: =+E15/$E$39 -> 0.047965328 | G15: Gastos Variables
A16: Luz, agua, Internet | B16: =+SUMIF($A$45:$A$90,A16,$B$45:$B$90) -> 184929 | C16: 184929 | D16: =+C16-B16 -> 0 | E16: =+MAX(B16:D16) -> 184929 | F16: =+E16/$E$39 -> 0.043228052 | G16: Gastos Fijos
A17: Gastos varios | B17: =+SUMIF($A$45:$A$90,A17,$B$45:$B$90) -> 131977 | C17: 180000 | D17: =+C17-B17 -> 48023 | E17: =+MAX(B17:D17) -> 180000 | F17: =+E17/$E$39 -> 0.042075874 | G17: Gastos Variables
A18: Entretenimiento | B18: =+SUMIF($A$45:$A$90,A18,$B$45:$B$90) -> 135825 | C18: 135825 | D18: =+C18-B18 -> 0 | E18: =+MAX(B18:D18) -> 135825 | F18: =+E18/$E$39 -> 0.031749753 | G18: Gastos Variables
A19: Restaurant | B19: =+SUMIF($A$45:$A$90,A19,$B$45:$B$90) -> 144857 | C19: =+B19 -> 144857 | D19: =+C19-B19 -> 0 | E19: =+MAX(B19:D19) -> 144857 | F19: =+E19/$E$39 -> 0.033861027 | G19: Gastos Variables
A20: Gas | B20: =+SUMIF($A$45:$A$90,A20,$B$45:$B$90) -> 92800 | C20: 92800 | D20: =+C20-B20 -> 0 | E20: =+MAX(B20:D20) -> 92800 | F20: =+E20/$E$39 -> 0.021692451 | G20: Gastos Fijos
A21: Alimentación | B21: =+SUMIF($A$45:$A$90,A21,$B$45:$B$90) -> 51154 | C21: 83000 | D21: =+C21-B21 -> 31846 | E21: =+MAX(B21:D21) -> 83000 | F21: =+E21/$E$39 -> 0.019401653 | G21: Gastos Fijos/Var.
A22: Farmacia, Salud y Belleza | B22: =+SUMIF($A$45:$A$90,A22,$B$45:$B$90) -> 43101 | C22: 80000 | D22: =+C22-B22 -> 36899 | E22: =+MAX(B22:D22) -> 80000 | F22: =+E22/$E$39 -> 0.018700388 | G22: Gastos Variables
A23: Regalos | B23: =+SUMIF($A$45:$A$90,A23,$B$45:$B$90) -> 58032 | C23: 58032 | D23: =+C23-B23 -> 0 | E23: =+MAX(B23:D23) -> 58032 | F23: =+E23/$E$39 -> 0.013565262 | G23: Gastos Variables
A24: Gimnasio | B24: =+SUMIF($A$45:$A$90,A24,$B$45:$B$90) -> 27589 | C24: 55178 | D24: =+C24-B24 -> 27589 | E24: =+MAX(B24:D24) -> 55178 | F24: =+E24/$E$39 -> 0.012898125 | G24: Gastos Fijos
A25: Credito Meli | B25: =+SUMIF($A$45:$A$90,A25,$B$45:$B$90) -> 43028 | C25: 43028 | D25: =+C25-B25 -> 0 | E25: =+MAX(B25:D25) -> 43028 | F25: =+E25/$E$39 -> 0.010058004 | G25: Gastos Variables
A26: Giro Cajero | B26: =+SUMIF($A$45:$A$90,A26,$B$45:$B$90) -> 30000 | C26: 30000 | D26: =+C26-B26 -> 0 | E26: =+MAX(B26:D26) -> 30000 | F26: =+E26/$E$39 -> 0.0070126457 | G26: Gastos Variables
A27: Jardinero | B27: =+SUMIF($A$45:$A$90,A27,$B$45:$B$90) -> 29200 | C27: 29200 | D27: =+C27-B27 -> 0 | E27: =+MAX(B27:D27) -> 29200 | F27: =+E27/$E$39 -> 0.0068256418 | G27: Gastos Variables
A28: Suscripción | B28: =+SUMIF($A$45:$A$90,A28,$B$45:$B$90) -> 11319 | C28: 25000 | D28: =+C28-B28 -> 13681 | E28: =+MAX(B28:D28) -> 25000 | F28: =+E28/$E$39 -> 0.0058438714 | G28: Gastos Fijos
A29: Hogar | B29: =+SUMIF($A$45:$A$90,A29,$B$45:$B$90) -> 19990 | C29: 19990 | D29: =+C29-B29 -> 0 | E29: =+MAX(B29:D29) -> 19990 | F29: =+E29/$E$39 -> 0.0046727596 | G29: Gastos Variables
A30: Estacionamiento | B30: =+SUMIF($A$45:$A$90,A30,$B$45:$B$90) -> 5200 | C30: 10000 | D30: =+C30-B30 -> 4800 | E30: =+MAX(B30:D30) -> 10000 | F30: =+E30/$E$39 -> 0.0023375486 | G30: Gastos Variables
A31: Cumple Fer | B31: =+SUMIF($A$45:$A$90,A31,$B$45:$B$90) -> 0 | C31: 0 | D31: =+C31-B31 -> 0 | E31: =+MAX(B31:D31) -> 0 | F31: =+E31/$E$39 -> 0 | G31: Gastos Variables
... A36: Adm. Tarjeta | B36: =+SUMIF($A$45:$A$90,A36,$B$45:$B$90) -> 13604 | C36: 13604 | D36: =+C36-B36 -> 0 | E36: =+MAX(B36:D36) -> 13604 | F36: =+E36/$E$39 -> 0.0031800011 | G36: Gastos Fijos
A37: Colegio | B37: =+SUMIF($A$45:$A$90,A37,$B$45:$B$90) -> 13830 | C37: =+B37 -> 13830 | D37: =+C37-B37 -> 0 | E37: =+MAX(B37:D37) -> 13830 | F37: =+E37/$E$39 -> 0.0032328297 | G37: Gastos Fijos/Var.
A39: Total general | B39: =SUM(B9:B37) -> 3909798 | C39: =SUM(C9:C37) -> 4277986 | D39: =SUM(D9:D37) -> 368188 | E39: =SUM(E9:E37) -> 4277986 | H39: 2770340
A41: ABONO/CARGO | B41: Cargo | I41: Ahorro | J41: Actual | K41: Importe
A42: DEB/CRED. | B42: (Todas) | I42: Fintual | J42: 267123 | K42: =160000+225000+12000-97725 -> 299275
A43: MES | B43: 2026.10 OCTUBRE | J43: =+J42-K42 -> -32152 | K43: =+J43/K42 -> -0.10743296
I44: Ganancia / Perdida Cap | K44: 8698.4529
A45: Etiquetas de fila | B45: Suma de MONTO ($) | C45: % | I45: Ganancia / Perdid | J45: =+J43+K44 -> -23453.547
A46: Gastos Variables | B46: 2235338 | C46: 0.57172724
A47: Bencina y Otros Auto | B47: 507685 | C47: 0.12984942
...

Sheet Dashboard Familiar
A1: CONTROL FINANCIERO FAMILIAR
A4: PARÁMETROS DEL MES | F4: INDICADORES CLAVE
A5: Mes de control | B5: 2026.09 SEPTIEMBRE | F5: Ingreso esperado ($) | G5: =+Hoja4!K2 -> 4287807 | H5: Ingreso fijo + Uber meta
A6: Sueldo líquido fijo ($) | B6: 3100000 | F6: Gasto real a la fecha ($) | G6: =+Hoja4!B39 -> 3909798 | H6: Acumulado registrado
A7: Meta Uber mensual ($) | B7: =25000*30 -> 750000 | F7: Gasto proyectado mes ($) | G7: =+Hoja4!C39 -> 4277986 | H7: Presupuesto total
A8: Meta de ahorro | B8: 0.05 | F8: Ahorro proyectado ($) | G8: =G5-G7 -> 9821 | H8: Positivo = ahorro
A9: Ahorro objetivo ($) | B9: =B6*B8 -> 155000 | F9: Uber requerido p/ equilibrio ($) | G9: =MAX(0,G7-B6) -> 1177986 | H9: Uber necesario sin recortes
F10: Recorte para meta ahorro ($) | G10: =MAX(0,G7-(G5-B9)) -> 145179 | H10: Ajuste requerido
A11: SEGUIMIENTO POR CATEGORÍA | F11: Presupuesto restante del mes ($) | G11: =MAX(0,(G5-B9)-G6) -> 223009 | H11: Disponible para resto del mes
A12: Categoría | B12: Real ($) | C12: Presupuesto ($) | D12: Disponible ($) | E12: % usado | F12: Tipo | G12: =IFERROR(G7/G5,0) -> 0.99770955 | H12: Ideal < 90%
A13: =Hoja4!A9 -> Arriendo | B13: =Hoja4!B9 -> 758000 | C13: =Hoja4!C9 -> 758000 | D13: =C13-B13 -> 0 | E13: =IFERROR(B13/C13,0) -> 1 | F13: =Hoja4!G9 -> Gastos Fijos
A14: =Hoja4!A10 -> Supermercado | B14: =Hoja4!B10 -> 466965 | C14: =Hoja4!C10 -> 600000 | D14: =C14-B14 -> 133035 | E14: =IFERROR(B14/C14,0) -> 0.778275 | F14: =Hoja4!G10 -> Gastos Variables | H14: PLAN DE AHORRO RECOMENDADO
A15: =Hoja4!A11 -> Bencina y Otros Auto | B15: =Hoja4!B11 -> 507685 | C15: =Hoja4!C11 -> 580000 | D15: =C15-B15 -> 72315 | E15: =IFERROR(B15/C15,0) -> 0.87531897 | F15: =Hoja4!G11 -> Gastos Variables | H15: Categoría | I15: Presupuesto actual | J15: Meta sugerida | K15: Ahorro potencial | L15: Acción
A16: =Hoja4!A12 -> Fintual | B16: =Hoja4!B12 -> 397000 | C16: =Hoja4!C12 -> 397000 | D16: =C16-B16 -> 0 | E16: =IFERROR(B16/C16,0) -> 1 | F16: =Hoja4!G12 -> Ahorro | H16: Supermercado | I16: 650000 | J16: 500000 | K16: 150000 | L16: Lista semanal + tope por compra
A17: =Hoja4!A13 -> Transf. Katy | B17: =Hoja4!B13 -> 332091 | C17: =Hoja4!C13 -> 332091 | D17: =C17-B17 -> 0 | E17: =IFERROR(B17/C17,0) -> 1 | F17: =Hoja4!G13 -> Gastos Fijos/Var. | H17: Bencina y Otros Auto | I17: 350000 | J17: 250000 | K17: 100000 | L17: Separar combustible de Uber y uso familiar
A18: =Hoja4!A14 -> Gastos Comun | B18: =Hoja4!B14 -> 206427 | C18: =Hoja4!C14 -> 206427 | D18: =C18-B18 -> 0 | E18: =IFERROR(B18/C18,0) -> 1 | F18: =Hoja4!G14 -> Gastos Fijos | H18: Gastos varios | I18: 150000 | J18: 75000 | K18: 75000 | L18: Crear tope semanal
A19: =Hoja4!A15 -> Ropa | B19: =Hoja4!B15 -> 205195 | C19: =Hoja4!C15 -> 205195 | D19: =C19-B19 -> 0 | E19: =IFERROR(B19/C19,0) -> 1 | F19: =Hoja4!G15 -> Gastos Variables | H19: Fiestas patrias | I19: 150000 | J19: 80000 | K19: 70000 | L19: Tratar como gasto extraordinario
A20: =Hoja4!A16 -> Luz, agua, Internet | B20: =Hoja4!B16 -> 184929 | C20: =Hoja4!C16 -> 184929 | D20: =C20-B20 -> 0 | E20: =IFERROR(B20/C20,0) -> 1 | F20: =Hoja4!G16 -> Gastos Fijos | H20: Ropa | I20: 100000 | J20: 50000 | K20: 50000 | L20: Compra solo con presupuesto disponible
A21: =Hoja4!A17 -> Gastos varios | B21: =Hoja4!B17 -> 131977 | C21: =Hoja4!C17 -> 180000 | D21: =C21-B21 -> 48023 | E21: =IFERROR(B21/C21,0) -> 0.73320556 | F21: =Hoja4!G17 -> Gastos Variables | H21: Entretenimiento | I21: 100000 | J21: 60000 | K21: 40000 | L21: Tope quincenal
A22: =Hoja4!A18 -> Entretenimiento | B22: =Hoja4!B18 -> 135825 | C22: =Hoja4!C18 -> 135825 | D22: =C22-B22 -> 0 | E22: =IFERROR(B22/C22,0) -> 1 | F22: =Hoja4!G18 -> Gastos Variables | H22: Restaurant | I22: 100000 | J22: 60000 | K22: 40000 | L22: Reducir delivery/comidas fuera
A23: =Hoja4!A19 -> Restaurant | B23: =Hoja4!B19 -> 144857 | C23: =Hoja4!C19 -> 144857 | D23: =C23-B23 -> 0 | E23: =IFERROR(B23/C23,0) -> 1 | F23: =Hoja4!G19 -> Gastos Variables | H23: Regalos | I23: 45000 | J23: 25000 | K23: 20000 | L23: Fondo mensual separado
A24: =Hoja4!A20 -> Gas | B24: =Hoja4!B20 -> 92800 | C24: =Hoja4!C20 -> 92800 | D24: =C24-B24 -> 0 | E24: =IFERROR(B24/C24,0) -> 1 | F24: =Hoja4!G20 -> Gastos Fijos | H24: TOTAL | K24: =SUM(K16:K23) -> 545000
A25: =Hoja4!A21 -> Alimentación | B25: =Hoja4!B21 -> 51154 | C25: =Hoja4!C21 -> 83000 | D25: =C25-B25 -> 31846 | E25: =IFERROR(B25/C25,0) -> 0.61631325 | F25: =Hoja4!G21 -> Gastos Fijos/Var.
A26: =Hoja4!A22 -> Farmacia, Salud y Belleza | B26: =Hoja4!B22 -> 43101 | C26: =Hoja4!C22 -> 80000 | D26: =C26-B26 -> 36899 | E26: =IFERROR(B26/C26,0) -> 0.5387625 | F26: =Hoja4!G22 -> Gastos Variables | H26: INDICADORES QUE CONVIENE SEGUIR CADA MES
A27: =Hoja4!A23 -> Regalos | B27: =Hoja4!B23 -> 58032 | C27: =Hoja4!C23 -> 58032 | D27: =C27-B27 -> 0 | E27: =IFERROR(B27/C27,0) -> 1 | F27: =Hoja4!G23 -> Gastos Variables | H27: Tasa de ahorro | I27: Ahorro / ingreso total | J27: Meta inicial 5%
A28: =Hoja4!A24 -> Gimnasio | B28: =Hoja4!B24 -> 27589 | C28: =Hoja4!C24 -> 55178 | D28: =C28-B28 -> 27589 | E28: =IFERROR(B28/C28,0) -> 0.5 | F28: =Hoja4!G24 -> Gastos Fijos | H28: Dependencia de Uber | I28: Uber / ingreso total | J28: Ideal < 15% para gastos básicos
A29: =Hoja4!A25 -> Credito Meli | B29: =Hoja4!B25 -> 43028 | C29: =Hoja4!C25 -> 43028 | D29: =C29-B29 -> 0 | E29: =IFERROR(B29/C29,0) -> 1 | F29: =Hoja4!G25 -> Gastos Variables | H29: Gasto variable / ingreso | I29: Gastos variables / ingreso | J29: Ideal < 35%-40%
A30: =Hoja4!A26 -> Giro Cajero | B30: =Hoja4!B26 -> 30000 | C30: =Hoja4!C26 -> 30000 | D30: =C30-B30 -> 0 | E30: =IFERROR(B30/C30,0) -> 1 | F30: =Hoja4!G26 -> Gastos Variables | H30: % presupuesto consumido | I30: Gasto real / presupuesto | J30: Alerta > 90% antes del día 25
A31: =Hoja4!A27 -> Jardinero | B31: =Hoja4!B27 -> 29200 | C31: =Hoja4!C27 -> 29200 | D31: =C31-B31 -> 0 | E31: =IFERROR(B31/C31,0) -> 1 | F31: =Hoja4!G27 -> Gastos Variables | H31: Gasto discrecional | I31: Ropa + restaurant + entret. + varios | J31: Definir tope mensual
A32: =Hoja4!A28 -> Suscripción | B32: =Hoja4!B28 -> 11319 | C32: =Hoja4!C28 -> 25000 | D32: =C32-B32 -> 13681 | E32: =IFERROR(B32/C32,0) -> 0.45276 | F32: =Hoja4!G28 -> Gastos Fijos | H32: Costo auto / Uber | I32: Bencina + estacionamiento + TAG | J32: Comparar con ingreso Uber neto
A33: =Hoja4!A29 -> Hogar | B33: =Hoja4!B29 -> 19990 | C33: =Hoja4!C29 -> 19990 | D33: =C33-B33 -> 0 | E33: =IFERROR(B33/C33,0) -> 1 | F33: =Hoja4!G29 -> Gastos Variables | H33: Fondo extraordinarios | I33: Cumpleaños + fiestas + regalos | J33: Provisionar mensual
A34: =Hoja4!A30 -> Estacionamiento | B34: =Hoja4!B30 -> 5200 | C34: =Hoja4!C30 -> 10000 | D34: =C34-B34 -> 4800 | E34: =IFERROR(B34/C34,0) -> 0.52 | F34: =Hoja4!G30 -> Gastos Variables
A35: =Hoja4!A31 -> Cumple Fer | B35: =Hoja4!B31 -> 0 | C35: =Hoja4!C31 -> 0 | D35: =C35-B35 -> 0 | E35: =IFERROR(B35/C35,0) -> 0 | F35: =Hoja4!G31 -> Gastos Variables
A36: =Hoja4!A32 -> Fiestas patrias | B36: =Hoja4!B32 -> 0 | C36: =Hoja4!C32 -> 0 | D36: =C36-B36 -> 0 | E36: =IFERROR(B36/C36,0) -> 0 | F36: =Hoja4!G32 -> Gastos Variables
A37: =Hoja4!A33 -> Rendición WM | B37: =Hoja4!B33 -> 0 | C37: =Hoja4!C33 -> 0 | D37: =C37-B37 -> 0 | E37: =IFERROR(B37/C37,0) -> 0 | F37: =Hoja4!G33 -> Gastos Variables
A38: =Hoja4!A34 -> TAG | B38: =Hoja4!B34 -> 0 | C38: =Hoja4!C34 -> 0 | D38: =C38-B38 -> 0 | E38: =IFERROR(B38/C38,0) -> 0 | F38: =Hoja4!G34 -> Gastos Fijos
A39: =Hoja4!A35 -> Deuda | B39: =Hoja4!B35 -> 0 | C39: =Hoja4!C35 -> 0 | D39: =C39-B39 -> 0 | E39: =IFERROR(B39/C39,0) -> 0 | F39: =Hoja4!G35 -> Gastos Variables
A40: =Hoja4!A36 -> Adm. Tarjeta | B40: =Hoja4!B36 -> 13604 | C40: =Hoja4!C36 -> 13604 | D40: =C40-B40 -> 0 | E40: =IFERROR(B40/C40,0) -> 1 | F40: =Hoja4!G36 -> Gastos Fijos
A41: =Hoja4!A37 -> Colegio | B41: =Hoja4!B37 -> 13830 | C41: =Hoja4!C37 -> 13830 | D41: =C41-B41 -> 0 | E41: =IFERROR(B41/C41,0) -> 1 | F41: =Hoja4!G37 -> Gastos Fijos/Var.
A44: Lectura recomendada: el sueldo fijo debe cubrir gastos base + ahorro. Uber debería financiar extras o acelerar ahorro, no sostener el presupuesto habitual.

Sheet Hoja2
C3: xx | D3: xx | E3: xx
B4: 2 | C4: 46316 | D4: Meli Dólar | E4: -38
B5: 8 | C5: 46316 | D5: Libreria Artelapiz | E5: 7630
B6: 21 | C6: 46316 | D6: Meli Dólar | E6: -4
B7: 27 | C7: 46316 | D7: Outletfit | E7: 700
B8: 34 | C8: 46316 | D8: Meli Dólar | E8: -22
B9: 40 | C9: 46316 | D9: Sodexochile | E9: 4459
B10: 47 | C10: 46316 | D10: Meli+ | E10: 2990
B11: 54 | C11: 46316 | D11: Meli Dólar | E11: -9
B12: 60 | C12: 46316 | D12: Sodexochile | E12: 1700
B13: 68 | C13: 46315 | D13: Uber Pagos Chile | E13: -93410
B14: 74 | C14: 46315 | D14: Mercado Pago | E14: -3
B15: 80 | C15: 46315 | D15: Meli Dólar | E15: -20
... B32: 199 | C32: 46314 | D32: Ingreso de dinero | E32: -106105

Sheet Hoja1
B4: Descripción | D4: 46296 | E4: 46266 | F4: 46235 | G4: 46204 | H4: 46174 | I4: 46143 | J4: 46113 | K4: 46082
B5: Arriendo | C5: =IFERROR(AVERAGEIF(D5:F5, "<>0"),0) -> 749666.67 | D5: =+VLOOKUP(Hoja1!B5,Hoja4!$A$9:$C$39,3,) -> 758000 | E5: 758000 | F5: 733000
B6: Supermercado | C6: =IFERROR(AVERAGEIF(D6:F6, "<>0"),0) -> 628158 | D6: =+VLOOKUP(Hoja1!B6,Hoja4!$A$9:$C$39,3,) -> 600000 | E6: 617589 | F6: 666885
B7: Bencina y Otros Auto | C7: =IFERROR(AVERAGEIF(D7:F7, "<>0"),0) -> 434416.67 | D7: =+VLOOKUP(Hoja1!B7,Hoja4!$A$9:$C$39,3,) -> 580000 | E7: 342777 | F7: 380473
B8: Cumple Fer | C8: =IFERROR(AVERAGEIF(D8:F8, "<>0"),0) -> 348647 | D8: =+VLOOKUP(Hoja1!B8,Hoja4!$A$9:$C$39,3,) -> 0 | E8: 348647 | F8: 0
B9: Transf. Katy | C9: =IFERROR(AVERAGEIF(D9:F9, "<>0"),0) -> 252130.67 | D9: =+VLOOKUP(Hoja1!B9,Hoja4!$A$9:$C$39,3,) -> 332091 | E9: 259311 | F9: 164990
B10: Gastos varios | C10: =IFERROR(AVERAGEIF(D10:F10, "<>0"),0) -> 184560.33 | D10: =+VLOOKUP(Hoja1!B10,Hoja4!$A$9:$C$39,3,) -> 180000 | E10: 179003 | F10: 194678
B11: Fiestas patrias | C11: =IFERROR(AVERAGEIF(D11:F11, "<>0"),0) -> 172540 | D11: =+VLOOKUP(Hoja1!B11,Hoja4!$A$9:$C$39,3,) -> 0 | E11: 172540 | F11: 0
B12: Restaurant | C12: =IFERROR(AVERAGEIF(D12:F12, "<>0"),0) -> 159491.33 | D12: =+VLOOKUP(Hoja1!B12,Hoja4!$A$9:$C$39,3,) -> 144857 | E12: 147473 | F12: 186144
B13: Farmacia, Salud y Belleza | C13: =IFERROR(AVERAGEIF(D13:F13, "<>0"),0) -> 110135.33 | D13: =+VLOOKUP(Hoja1!B13,Hoja4!$A$9:$C$39,3,) -> 80000 | E13: 121163 | F13: 129243
B14: Ropa | C14: =IFERROR(AVERAGEIF(D14:F14, "<>0"),0) -> 158119 | D14: =+VLOOKUP(Hoja1!B14,Hoja4!$A$9:$C$39,3,) -> 205195 | E14: 108772 | F14: 160390
B15: Entretenimiento | C15: =IFERROR(AVERAGEIF(D15:F15, "<>0"),0) -> 88958.333 | D15: =+VLOOKUP(Hoja1!B15,Hoja4!$A$9:$C$39,3,) -> 135825 | E15: 96490 | F15: 34560
B16: Alimentación | C16: =IFERROR(AVERAGEIF(D16:F16, "<>0"),0) -> 81130.333 | D16: =+VLOOKUP(Hoja1!B16,Hoja4!$A$9:$C$39,3,) -> 83000 | E16: 75670 | F16: 84721
... B33: Jardinero | C33: =IFERROR(AVERAGEIF(D33:F33, "<>0"),0) -> 29200 | D33: =+VLOOKUP(Hoja1!B33,Hoja4!$A$9:$C$39,3,) -> 29200 | E33: 0 | F33: 0
C34: =SUM(C5:C33) -> 4661344.5 | D34: =SUM(D5:D33) -> 4277986 | E34: =SUM(E5:E33) -> 3595500 | F34: =SUM(F5:F33) -> 3963602
